[2024-07-25T08:43:46.138+0000] {local_task_job_runner.py:120} INFO - ::group::Pre task execution logs
[2024-07-25T08:43:46.184+0000] {taskinstance.py:2076} INFO - Dependencies all met for dep_context=non-requeueable deps ti=<TaskInstance: raw_data_processing_pipeline.extract_from_raw_data manual__2024-07-25T08:43:44.412529+00:00 [queued]>
[2024-07-25T08:43:46.197+0000] {taskinstance.py:2076} INFO - Dependencies all met for dep_context=requeueable deps ti=<TaskInstance: raw_data_processing_pipeline.extract_from_raw_data manual__2024-07-25T08:43:44.412529+00:00 [queued]>
[2024-07-25T08:43:46.198+0000] {taskinstance.py:2306} INFO - Starting attempt 1 of 1
[2024-07-25T08:43:46.219+0000] {taskinstance.py:2330} INFO - Executing <Task(PythonOperator): extract_from_raw_data> on 2024-07-25 08:43:44.412529+00:00
[2024-07-25T08:43:46.227+0000] {standard_task_runner.py:64} INFO - Started process 783 to run task
[2024-07-25T08:43:46.233+0000] {standard_task_runner.py:90} INFO - Running: ['airflow', 'tasks', 'run', 'raw_data_processing_pipeline', 'extract_from_raw_data', 'manual__2024-07-25T08:43:44.412529+00:00', '--job-id', '8', '--raw', '--subdir', 'DAGS_FOLDER/raw_data_processing_pipeline.py', '--cfg-path', '/tmp/tmpm23ehvb_']
[2024-07-25T08:43:46.237+0000] {standard_task_runner.py:91} INFO - Job 8: Subtask extract_from_raw_data
[2024-07-25T08:43:46.341+0000] {task_command.py:426} INFO - Running <TaskInstance: raw_data_processing_pipeline.extract_from_raw_data manual__2024-07-25T08:43:44.412529+00:00 [running]> on host a2e39b95bff0
[2024-07-25T08:43:46.514+0000] {taskinstance.py:2648} INFO - Exporting env vars: AIRFLOW_CTX_DAG_OWNER='airflow' AIRFLOW_CTX_DAG_ID='raw_data_processing_pipeline' AIRFLOW_CTX_TASK_ID='extract_from_raw_data' AIRFLOW_CTX_EXECUTION_DATE='2024-07-25T08:43:44.412529+00:00' AIRFLOW_CTX_TRY_NUMBER='1' AIRFLOW_CTX_DAG_RUN_ID='manual__2024-07-25T08:43:44.412529+00:00'
[2024-07-25T08:43:46.516+0000] {taskinstance.py:430} INFO - ::endgroup::
[2024-07-25T08:43:46.561+0000] {taskinstance.py:441} INFO - ::group::Post task execution logs
[2024-07-25T08:43:46.562+0000] {taskinstance.py:2905} ERROR - Task failed with exception
Traceback (most recent call last):
  File "/root/.cache/pypoetry/virtualenvs/freeprise-matchmaker-BsnH11MF-py3.8/lib/python3.8/site-packages/airflow/models/taskinstance.py", line 465, in _execute_task
    result = _execute_callable(context=context, **execute_callable_kwargs)
  File "/root/.cache/pypoetry/virtualenvs/freeprise-matchmaker-BsnH11MF-py3.8/lib/python3.8/site-packages/airflow/models/taskinstance.py", line 432, in _execute_callable
    return execute_callable(context=context, **execute_callable_kwargs)
  File "/root/.cache/pypoetry/virtualenvs/freeprise-matchmaker-BsnH11MF-py3.8/lib/python3.8/site-packages/airflow/models/baseoperator.py", line 401, in wrapper
    return func(self, *args, **kwargs)
  File "/root/.cache/pypoetry/virtualenvs/freeprise-matchmaker-BsnH11MF-py3.8/lib/python3.8/site-packages/airflow/operators/python.py", line 235, in execute
    return_value = self.execute_callable()
  File "/root/.cache/pypoetry/virtualenvs/freeprise-matchmaker-BsnH11MF-py3.8/lib/python3.8/site-packages/airflow/operators/python.py", line 252, in execute_callable
    return self.python_callable(*self.op_args, **self.op_kwargs)
  File "/app/airflow/raw_data_processing/extract_from_raw_data.py", line 14, in extract_from_raw_data
    df = pd.read_csv(input_csv)
  File "/root/.cache/pypoetry/virtualenvs/freeprise-matchmaker-BsnH11MF-py3.8/lib/python3.8/site-packages/pandas/util/_decorators.py", line 311, in wrapper
    return func(*args, **kwargs)
  File "/root/.cache/pypoetry/virtualenvs/freeprise-matchmaker-BsnH11MF-py3.8/lib/python3.8/site-packages/pandas/io/parsers/readers.py", line 586, in read_csv
    return _read(filepath_or_buffer, kwds)
  File "/root/.cache/pypoetry/virtualenvs/freeprise-matchmaker-BsnH11MF-py3.8/lib/python3.8/site-packages/pandas/io/parsers/readers.py", line 482, in _read
    parser = TextFileReader(filepath_or_buffer, **kwds)
  File "/root/.cache/pypoetry/virtualenvs/freeprise-matchmaker-BsnH11MF-py3.8/lib/python3.8/site-packages/pandas/io/parsers/readers.py", line 811, in __init__
    self._engine = self._make_engine(self.engine)
  File "/root/.cache/pypoetry/virtualenvs/freeprise-matchmaker-BsnH11MF-py3.8/lib/python3.8/site-packages/pandas/io/parsers/readers.py", line 1040, in _make_engine
    return mapping[engine](self.f, **self.options)  # type: ignore[call-arg]
  File "/root/.cache/pypoetry/virtualenvs/freeprise-matchmaker-BsnH11MF-py3.8/lib/python3.8/site-packages/pandas/io/parsers/c_parser_wrapper.py", line 51, in __init__
    self._open_handles(src, kwds)
  File "/root/.cache/pypoetry/virtualenvs/freeprise-matchmaker-BsnH11MF-py3.8/lib/python3.8/site-packages/pandas/io/parsers/base_parser.py", line 222, in _open_handles
    self.handles = get_handle(
  File "/root/.cache/pypoetry/virtualenvs/freeprise-matchmaker-BsnH11MF-py3.8/lib/python3.8/site-packages/pandas/io/common.py", line 702, in get_handle
    handle = open(
FileNotFoundError: [Errno 2] No such file or directory: 'data/raw/raw_profiles.csv'
[2024-07-25T08:43:46.585+0000] {taskinstance.py:1206} INFO - Marking task as FAILED. dag_id=raw_data_processing_pipeline, task_id=extract_from_raw_data, run_id=manual__2024-07-25T08:43:44.412529+00:00, execution_date=20240725T084344, start_date=20240725T084346, end_date=20240725T084346
[2024-07-25T08:43:46.610+0000] {standard_task_runner.py:110} ERROR - Failed to execute job 8 for task extract_from_raw_data ([Errno 2] No such file or directory: 'data/raw/raw_profiles.csv'; 783)
[2024-07-25T08:43:46.647+0000] {local_task_job_runner.py:243} INFO - Task exited with return code 1
[2024-07-25T08:43:46.694+0000] {taskinstance.py:3503} INFO - 0 downstream tasks scheduled from follow-on schedule check
[2024-07-25T08:43:46.700+0000] {local_task_job_runner.py:222} INFO - ::endgroup::
